Workbook
Name Slicer_Remote_Work: #N/A

Sheet Raw_Data
A1: Employee_ID | B1: First_Name | C1: Last_Name | D1: Age | E1: Department_Region | F1: Status | G1: Join_Date | H1: Salary | I1: Email | J1: Phone | K1: Performance_Score | L1: Remote_Work
A2: EMP1000 | B2: Bob | C2: Davis | D2: 25 | E2: DevOps-California | F2: Active | G2: 44288 | H2: 59767.65 | I2: bob.davis@example.com | J2: -1651623197 | K2: Average | L2: TRUE
A3: EMP1001 | B3: Bob | C3: Brown | E3: Finance-Texas | F3: Active | G3: 44022 | H3: 65304.66 | I3: bob.brown@example.com | J3: -1898471390 | K3: Excellent | L3: TRUE
A4: EMP1002 | B4: Alice | C4: Jones | E4: Admin-Nevada | F4: Pending | G4: 45267 | H4: 88145.9 | I4: alice.jones@example.com | J4: -5596363211 | K4: Good | L4: TRUE
A5: EMP1003 | B5: Eva | C5: Davis | D5: 25 | E5: Admin-Nevada | F5: Inactive | G5: 44527 | H5: 69450.99 | I5: eva.davis@example.com | J5: -3476490784 | K5: Good | L5: TRUE
A6: EMP1004 | B6: Frank | C6: Williams | D6: 25 | E6: Cloud Tech-Florida | F6: Active | G6: 44566 | H6: 109324.61 | I6: frank.williams@example.com | J6: -1586734256 | K6: Poor | L6: FALSE
A7: EMP1005 | B7: Alice | C7: Garcia | D7: 40 | E7: Sales-Texas | F7: Inactive | G7: 43992 | H7: 88642.84 | I7: alice.garcia@example.com | J7: -5409003485 | K7: Good | L7: FALSE
A8: EMP1006 | B8: Frank | C8: Jones | E8: Admin-Nevada | F8: Active | G8: 43924 | H8: 96288.43 | I8: frank.jones@example.com | J8: -4518376063 | K8: Good | L8: FALSE
A9: EMP1007 | B9: Bob | C9: Jones | D9: 30 | E9: Cloud Tech-Florida | F9: Inactive | G9: 44759 | H9: 94497.91 | I9: bob.jones@example.com | J9: -4134327559 | K9: Average | L9: TRUE
A10: EMP1008 | B10: Frank | C10: Davis | D10: 35 | E10: Admin-Nevada | F10: Inactive | G10: 45268 | H10: 115565.82 | I10: frank.davis@example.com | J10: -4177656123 | K10: Excellent | L10: TRUE
A11: EMP1009 | B11: Charlie | C11: Johnson | E11: DevOps-New York | F11: Active | G11: 44777 | H11: 76561.88 | I11: charlie.johnson@example.com | J11: -8156985699 | K11: Excellent | L11: TRUE
A12: EMP1010 | B12: David | C12: Williams | D12: 35 | E12: Cloud Tech-New York | F12: Active | G12: 45479 | H12: 72081.71 | I12: david.williams@example.com | J12: -2720634590 | K12: Average | L12: FALSE
A13: EMP1011 | B13: David | C13: Davis | E13: DevOps-California | F13: Active | G13: 45173 | H13: 84946.19 | I13: david.davis@example.com | J13: -1238296576 | K13: Poor | L13: TRUE
A14: EMP1012 | B14: Heidi | C14: Williams | D14: 30 | E14: HR-New York | F14: Active | G14: 45356 | H14: 89295.77 | I14: heidi.williams@example.com | J14: -2429543164 | K14: Excellent | L14: FALSE
A15: EMP1013 | B15: Grace | C15: Williams | E15: Finance-California | F15: Active | G15: 44114 | H15: 85666.84 | I15: grace.williams@example.com | J15: -2669300892 | K15: Good | L15: FALSE
A16: EMP1014 | B16: Alice | C16: Garcia | D16: 25 | E16: Admin-Nevada | F16: Active | G16: 45453 | H16: 97633.68 | I16: alice.garcia@example.com | J16: -1734206968 | K16: Excellent | L16: TRUE
A17: EMP1015 | B17: Grace | C17: Jones | D17: 40 | E17: Sales-Florida | F17: Pending | G17: 44345 | H17: 117975.49 | I17: grace.jones@example.com | J17: -4215291085 | K17: Good | L17: TRUE
A18: EMP1016 | B18: Alice | C18: Brown | D18: 25 | E18: DevOps-Illinois | F18: Inactive | G18: 45405 | H18: 94867.33 | I18: alice.brown@example.com | J18: -7713334475 | K18: Poor | L18: FALSE
A19: EMP1017 | B19: Grace | C19: Garcia | D19: 30 | E19: Finance-Texas | F19: Pending | G19: 45624 | H19: 100377.65 | I19: grace.garcia@example.com | J19: -2639343625 | K19: Average | L19: TRUE
A20: EMP1018 | B20: Charlie | C20: Garcia | E20: Cloud Tech-Nevada | F20: Inactive | G20: 45554 | H20: 94726.46 | I20: charlie.garcia@example.com | J20: -2044397358 | K20: Excellent | L20: FALSE
A21: EMP1019 | B21: Charlie | C21: Williams | D21: 35 | E21: Admin-Illinois | F21: Pending | G21: 43832 | H21: 91926.12 | I21: charlie.williams@example.com | J21: -7107256365 | K21: Average | L21: TRUE
A22: EMP1020 | B22: Bob | C22: Miller | D22: 35 | E22: HR-New York | F22: Active | G22: 44324 | H22: 111460.67 | I22: bob.miller@example.com | J22: -9411800536 | K22: Excellent | L22: TRUE
A23: EMP1021 | B23: Bob | C23: Jones | D23: 40 | E23: Cloud Tech-Illinois | F23: Active | G23: 44093 | H23: 96182.56 | I23: bob.jones@example.com | J23: -5990048963 | K23: Good | L23: FALSE
A24: EMP1022 | B24: Charlie | C24: Johnson | D24: 35 | E24: Sales-Illinois | F24: Inactive | G24: 44264 | H24: 115023.94 | I24: charlie.johnson@example.com | J24: -6528092427 | K24: Average | L24: TRUE
A25: EMP1023 | B25: David | C25: Garcia | D25: 35 | E25: Finance-Nevada | F25: Pending | G25: 44595 | H25: 80667.01 | I25: david.garcia@example.com | J25: -7572158623 | K25: Excellent | L25: FALSE
A26: EMP1024 | B26: Bob | C26: Brown | D26: 30 | E26: Admin-Texas | F26: Inactive | G26: 43874 | H26: 91181.61 | I26: bob.brown@example.com | J26: -1502745643 | K26: Good | L26: TRUE
A27: EMP1025 | B27: David | C27: Miller | D27: 25 | E27: Cloud Tech-Nevada | F27: Pending | G27: 43951 | H27: 66025.92 | I27: david.miller@example.com | J27: -9485625727 | K27: Average | L27: FALSE
A28: EMP1026 | B28: Frank | C28: Miller | D28: 25 | E28: Sales-New York | F28: Inactive | G28: 45201 | H28: 83979.01 | I28: frank.miller@example.com | J28: -7032032073 | K28: Average | L28: FALSE
A29: EMP1027 | B29: Heidi | C29: Johnson | D29: 30 | E29: Finance-Florida | F29: Active | G29: 44024 | H29: 56785.16 | I29: heidi.johnson@example.com | J29: -2761707586 | K29: Excellent | L29: TRUE
A30: EMP1028 | B30: Grace | C30: Garcia | D30: 40 | E30: Finance-Nevada | F30: Active | G30: 45210 | H30: 95741.88 | I30: grace.garcia@example.com | J30: -7712151341 | K30: Excellent | L30: FALSE
A31: EMP1029 | B31: Alice | C31: Brown | D31: 40 | E31: DevOps-California | F31: Active | G31: 44340 | H31: 63411.31 | I31: alice.brown@example.com | J31: -2849939088 | K31: Excellent | L31: TRUE
A32: EMP1030 | B32: Charlie | C32: Jones | D32: 40 | E32: Admin-California | F32: Inactive | G32: 44342 | H32: 111214.02 | I32: charlie.jones@example.com | J32: -2613715040 | K32: Good | L32: TRUE
... A37: EMP1035 | B37: Frank | C37: Jones | D37: 25 | E37: Cloud Tech-Illinois | F37: Inactive | G37: 44860 | H37: 114357.1 | I37: frank.jones@example.com | J37: -6642147648 | K37: Excellent | L37: TRUE
A38: EMP1036 | B38: Alice | C38: Brown | E38: Cloud Tech-New York | F38: Active | G38: 45049 | H38: 54757.26 | I38: alice.brown@example.com | J38: -2515837766 | K38: Poor | L38: FALSE
A39: EMP1037 | B39: Grace | C39: Smith | D39: 25 | E39: Sales-New York | F39: Pending | G39: 45048 | H39: 52781.92 | I39: grace.smith@example.com | J39: -4996165925 | K39: Average | L39: TRUE
A40: EMP1038 | B40: Frank | C40: Smith | D40: 35 | E40: Admin-Nevada | F40: Pending | G40: 44474 | H40: 66708.02 | I40: frank.smith@example.com | J40: -6108573277 | K40: Good | L40: TRUE
A41: EMP1039 | B41: Eva | C41: Williams | D41: 40 | E41: HR-Texas | F41: Active | G41: 44769 | H41: 93481.15 | I41: eva.williams@example.com | J41: -8147617421 | K41: Poor | L41: FALSE
A42: EMP1040 | B42: Bob | C42: Williams | D42: 25 | E42: Sales-New York | F42: Pending | G42: 44374 | H42: 59271.96 | I42: bob.williams@example.com | J42: -4386490809 | K42: Excellent | L42: TRUE
A43: EMP1041 | B43: Bob | C43: Davis | D43: 30 | E43: HR-California | F43: Active | G43: 44728 | H43: 108362.15 | I43: bob.davis@example.com | J43: -8186617944 | K43: Excellent | L43: FALSE
A44: EMP1042 | B44: Alice | C44: Johnson | E44: HR-Nevada | F44: Active | G44: 45629 | H44: 59400.38 | I44: alice.johnson@example.com | J44: -4918017225 | K44: Average | L44: TRUE
...

Sheet Cleaned_Data
A1: Employee_ID | B1: First_Name | C1: Last_Name | D1: Age | E1: Department | F1: Region | G1: Status | H1: Join_Date | I1: Salary | J1: Email | K1: Phone | L1: Performance_Score | M1: Remote_Work
A2: =IFERROR(TRIM(Raw_Data!A2), "Review") -> EMP1000 | B2: =IFERROR(TRIM(Raw_Data!B2), "Review") -> Bob | C2: =IFERROR(TRIM(Raw_Data!C2), "Review") -> Davis | D2: =IF(Raw_Data!D2="", "", IFERROR(VALUE(Raw_Data!D2), "")) -> 25 | E2: =IFERROR(LEFT(Raw_Data!E2,SEARCH("-",Raw_Data!E2)-1),"Review") -> DevOps | F2: =IFERROR(_xlfn.TEXTAFTER(Raw_Data!E2,"-"),"Review") -> California | G2: =IFERROR(TRIM(Raw_Data!F2), "Review") -> Active | H2: =IFERROR(TEXT(Raw_Data!G2, "YYYY-MM-DD"),"Review") -> 2021-04-02 | I2: =IF(Raw_Data!H2="", "", IFERROR(VALUE(Raw_Data!H2), "")) -> 59767.65 | J2: =IF(Raw_Data!I2="", "", IF(ISNUMBER(FIND("@", Raw_Data!I2)), Raw_Data!I2, "Review")) -> bob.davis@example.com | K2: =IFERROR(TEXT(ABS(Raw_Data!J2), "0"), "Review") -> 1651623197 | L2: =IFERROR(TRIM(Raw_Data!K2), "Review") -> Average | M2: =IF(Raw_Data!L2="", "", IF(ISLOGICAL(Raw_Data!L2), Raw_Data!L2, IF(OR(UPPER(Raw_Data!L2)="TRUE", UPPER(Raw_Data!L2)="YES", UPPER(Raw_Data!L2)="1"), TRUE, IF(OR(UPPER(Raw_Data!L2)="FALSE", UPPER(Raw_Data!L2)="NO", UPPER(Raw_Data!L2)="0"), FALSE, "Review") ) ) ) -> TRUE
A3: =IFERROR(TRIM(Raw_Data!A3), "Review") -> EMP1001 | B3: =IFERROR(TRIM(Raw_Data!B3), "Review") -> Bob | C3: =IFERROR(TRIM(Raw_Data!C3), "Review") -> Brown | D3: =IF(Raw_Data!D3="", "", IFERROR(VALUE(Raw_Data!D3), "")) | E3: =IFERROR(LEFT(Raw_Data!E3,SEARCH("-",Raw_Data!E3)-1),"Review") -> Finance | F3: =IFERROR(_xlfn.TEXTAFTER(Raw_Data!E3,"-"),"Review") -> Texas | G3: =IFERROR(TRIM(Raw_Data!F3), "Review") -> Active | H3: =IFERROR(TEXT(Raw_Data!G3, "YYYY-MM-DD"),"Review") -> 2020-07-10 | I3: =IF(Raw_Data!H3="", "", IFERROR(VALUE(Raw_Data!H3), "")) -> 65304.66 | J3: =IF(Raw_Data!I3="", "", IF(ISNUMBER(FIND("@", Raw_Data!I3)), Raw_Data!I3, "Review")) -> bob.brown@example.com | K3: =IFERROR(TEXT(ABS(Raw_Data!J3), "0"), "Review") -> 1898471390 | L3: =IFERROR(TRIM(Raw_Data!K3), "Review") -> Excellent | M3: =IF(Raw_Data!L3="", "", IF(ISLOGICAL(Raw_Data!L3), Raw_Data!L3, IF(OR(UPPER(Raw_Data!L3)="TRUE", UPPER(Raw_Data!L3)="YES", UPPER(Raw_Data!L3)="1"), TRUE, IF(OR(UPPER(Raw_Data!L3)="FALSE", UPPER(Raw_Data!L3)="NO", UPPER(Raw_Data!L3)="0"), FALSE, "Review") ) ) ) -> TRUE
A4: =IFERROR(TRIM(Raw_Data!A4), "Review") -> EMP1002 | B4: =IFERROR(TRIM(Raw_Data!B4), "Review") -> Alice | C4: =IFERROR(TRIM(Raw_Data!C4), "Review") -> Jones | D4: =IF(Raw_Data!D4="", "", IFERROR(VALUE(Raw_Data!D4), "")) | E4: =IFERROR(LEFT(Raw_Data!E4,SEARCH("-",Raw_Data!E4)-1),"Review") -> Admin | F4: =IFERROR(_xlfn.TEXTAFTER(Raw_Data!E4,"-"),"Review") -> Nevada | G4: =IFERROR(TRIM(Raw_Data!F4), "Review") -> Pending | H4: =IFERROR(TEXT(Raw_Data!G4, "YYYY-MM-DD"),"Review") -> 2023-12-07 | I4: =IF(Raw_Data!H4="", "", IFERROR(VALUE(Raw_Data!H4), "")) -> 88145.9 | J4: =IF(Raw_Data!I4="", "", IF(ISNUMBER(FIND("@", Raw_Data!I4)), Raw_Data!I4, "Review")) -> alice.jones@example.com | K4: =IFERROR(TEXT(ABS(Raw_Data!J4), "0"), "Review") -> 5596363211 | L4: =IFERROR(TRIM(Raw_Data!K4), "Review") -> Good | M4: =IF(Raw_Data!L4="", "", IF(ISLOGICAL(Raw_Data!L4), Raw_Data!L4, IF(OR(UPPER(Raw_Data!L4)="TRUE", UPPER(Raw_Data!L4)="YES", UPPER(Raw_Data!L4)="1"), TRUE, IF(OR(UPPER(Raw_Data!L4)="FALSE", UPPER(Raw_Data!L4)="NO", UPPER(Raw_Data!L4)="0"), FALSE, "Review") ) ) ) -> TRUE
A5: =IFERROR(TRIM(Raw_Data!A5), "Review") -> EMP1003 | B5: =IFERROR(TRIM(Raw_Data!B5), "Review") -> Eva | C5: =IFERROR(TRIM(Raw_Data!C5), "Review") -> Davis | D5: =IF(Raw_Data!D5="", "", IFERROR(VALUE(Raw_Data!D5), "")) -> 25 | E5: =IFERROR(LEFT(Raw_Data!E5,SEARCH("-",Raw_Data!E5)-1),"Review") -> Admin | F5: =IFERROR(_xlfn.TEXTAFTER(Raw_Data!E5,"-"),"Review") -> Nevada | G5: =IFERROR(TRIM(Raw_Data!F5), "Review") -> Inactive | H5: =IFERROR(TEXT(Raw_Data!G5, "YYYY-MM-DD"),"Review") -> 2021-11-27 | I5: =IF(Raw_Data!H5="", "", IFERROR(VALUE(Raw_Data!H5), "")) -> 69450.99 | J5: =IF(Raw_Data!I5="", "", IF(ISNUMBER(FIND("@", Raw_Data!I5)), Raw_Data!I5, "Review")) -> eva.davis@example.com | K5: =IFERROR(TEXT(ABS(Raw_Data!J5), "0"), "Review") -> 3476490784 | L5: =IFERROR(TRIM(Raw_Data!K5), "Review") -> Good | M5: =IF(Raw_Data!L5="", "", IF(ISLOGICAL(Raw_Data!L5), Raw_Data!L5, IF(OR(UPPER(Raw_Data!L5)="TRUE", UPPER(Raw_Data!L5)="YES", UPPER(Raw_Data!L5)="1"), TRUE, IF(OR(UPPER(Raw_Data!L5)="FALSE", UPPER(Raw_Data!L5)="NO", UPPER(Raw_Data!L5)="0"), FALSE, "Review") ) ) ) -> TRUE
A6: =IFERROR(TRIM(Raw_Data!A6), "Review") -> EMP1004 | B6: =IFERROR(TRIM(Raw_Data!B6), "Review") -> Frank | C6: =IFERROR(TRIM(Raw_Data!C6), "Review") -> Williams | D6: =IF(Raw_Data!D6="", "", IFERROR(VALUE(Raw_Data!D6), "")) -> 25 | E6: =IFERROR(LEFT(Raw_Data!E6,SEARCH("-",Raw_Data!E6)-1),"Review") -> Cloud Tech | F6: =IFERROR(_xlfn.TEXTAFTER(Raw_Data!E6,"-"),"Review") -> Florida | G6: =IFERROR(TRIM(Raw_Data!F6), "Review") -> Active | H6: =IFERROR(TEXT(Raw_Data!G6, "YYYY-MM-DD"),"Review") -> 2022-01-05 | I6: =IF(Raw_Data!H6="", "", IFERROR(VALUE(Raw_Data!H6), "")) -> 109324.61 | J6: =IF(Raw_Data!I6="", "", IF(ISNUMBER(FIND("@", Raw_Data!I6)), Raw_Data!I6, "Review")) -> frank.williams@example.com | K6: =IFERROR(TEXT(ABS(Raw_Data!J6), "0"), "Review") -> 1586734256 | L6: =IFERROR(TRIM(Raw_Data!K6), "Review") -> Poor | M6: =IF(Raw_Data!L6="", "", IF(ISLOGICAL(Raw_Data!L6), Raw_Data!L6, IF(OR(UPPER(Raw_Data!L6)="TRUE", UPPER(Raw_Data!L6)="YES", UPPER(Raw_Data!L6)="1"), TRUE, IF(OR(UPPER(Raw_Data!L6)="FALSE", UPPER(Raw_Data!L6)="NO", UPPER(Raw_Data!L6)="0"), FALSE, "Review") ) ) ) -> FALSE
A7: =IFERROR(TRIM(Raw_Data!A7), "Review") -> EMP1005 | B7: =IFERROR(TRIM(Raw_Data!B7), "Review") -> Alice | C7: =IFERROR(TRIM(Raw_Data!C7), "Review") -> Garcia | D7: =IF(Raw_Data!D7="", "", IFERROR(VALUE(Raw_Data!D7), "")) -> 40 | E7: =IFERROR(LEFT(Raw_Data!E7,SEARCH("-",Raw_Data!E7)-1),"Review") -> Sales | F7: =IFERROR(_xlfn.TEXTAFTER(Raw_Data!E7,"-"),"Review") -> Texas | G7: =IFERROR(TRIM(Raw_Data!F7), "Review") -> Inactive | H7: =IFERROR(TEXT(Raw_Data!G7, "YYYY-MM-DD"),"Review") -> 2020-06-10 | I7: =IF(Raw_Data!H7="", "", IFERROR(VALUE(Raw_Data!H7), "")) -> 88642.84 | J7: =IF(Raw_Data!I7="", "", IF(ISNUMBER(FIND("@", Raw_Data!I7)), Raw_Data!I7, "Review")) -> alice.garcia@example.com | K7: =IFERROR(TEXT(ABS(Raw_Data!J7), "0"), "Review") -> 5409003485 | L7: =IFERROR(TRIM(Raw_Data!K7), "Review") -> Good | M7: =IF(Raw_Data!L7="", "", IF(ISLOGICAL(Raw_Data!L7), Raw_Data!L7, IF(OR(UPPER(Raw_Data!L7)="TRUE", UPPER(Raw_Data!L7)="YES", UPPER(Raw_Data!L7)="1"), TRUE, IF(OR(UPPER(Raw_Data!L7)="FALSE", UPPER(Raw_Data!L7)="NO", UPPER(Raw_Data!L7)="0"), FALSE, "Review") ) ) ) -> FALSE
A8: =IFERROR(TRIM(Raw_Data!A8), "Review") -> EMP1006 | B8: =IFERROR(TRIM(Raw_Data!B8), "Review") -> Frank | C8: =IFERROR(TRIM(Raw_Data!C8), "Review") -> Jones | D8: =IF(Raw_Data!D8="", "", IFERROR(VALUE(Raw_Data!D8), "")) | E8: =IFERROR(LEFT(Raw_Data!E8,SEARCH("-",Raw_Data!E8)-1),"Review") -> Admin | F8: =IFERROR(_xlfn.TEXTAFTER(Raw_Data!E8,"-"),"Review") -> Nevada | G8: =IFERROR(TRIM(Raw_Data!F8), "Review") -> Active | H8: =IFERROR(TEXT(Raw_Data!G8, "YYYY-MM-DD"),"Review") -> 2020-04-03 | I8: =IF(Raw_Data!H8="", "", IFERROR(VALUE(Raw_Data!H8), "")) -> 96288.43 | J8: =IF(Raw_Data!I8="", "", IF(ISNUMBER(FIND("@", Raw_Data!I8)), Raw_Data!I8, "Review")) -> frank.jones@example.com | K8: =IFERROR(TEXT(ABS(Raw_Data!J8), "0"), "Review") -> 4518376063 | L8: =IFERROR(TRIM(Raw_Data!K8), "Review") -> Good | M8: =IF(Raw_Data!L8="", "", IF(ISLOGICAL(Raw_Data!L8), Raw_Data!L8, IF(OR(UPPER(Raw_Data!L8)="TRUE", UPPER(Raw_Data!L8)="YES", UPPER(Raw_Data!L8)="1"), TRUE, IF(OR(UPPER(Raw_Data!L8)="FALSE", UPPER(Raw_Data!L8)="NO", UPPER(Raw_Data!L8)="0"), FALSE, "Review") ) ) ) -> FALSE
A9: =IFERROR(TRIM(Raw_Data!A9), "Review") -> EMP1007 | B9: =IFERROR(TRIM(Raw_Data!B9), "Review") -> Bob | C9: =IFERROR(TRIM(Raw_Data!C9), "Review") -> Jones | D9: =IF(Raw_Data!D9="", "", IFERROR(VALUE(Raw_Data!D9), "")) -> 30 | E9: =IFERROR(LEFT(Raw_Data!E9,SEARCH("-",Raw_Data!E9)-1),"Review") -> Cloud Tech | F9: =IFERROR(_xlfn.TEXTAFTER(Raw_Data!E9,"-"),"Review") -> Florida | G9: =IFERROR(TRIM(Raw_Data!F9), "Review") -> Inactive | H9: =IFERROR(TEXT(Raw_Data!G9, "YYYY-MM-DD"),"Review") -> 2022-07-17 | I9: =IF(Raw_Data!H9="", "", IFERROR(VALUE(Raw_Data!H9), "")) -> 94497.91 | J9: =IF(Raw_Data!I9="", "", IF(ISNUMBER(FIND("@", Raw_Data!I9)), Raw_Data!I9, "Review")) -> bob.jones@example.com | K9: =IFERROR(TEXT(ABS(Raw_Data!J9), "0"), "Review") -> 4134327559 | L9: =IFERROR(TRIM(Raw_Data!K9), "Review") -> Average | M9: =IF(Raw_Data!L9="", "", IF(ISLOGICAL(Raw_Data!L9), Raw_Data!L9, IF(OR(UPPER(Raw_Data!L9)="TRUE", UPPER(Raw_Data!L9)="YES", UPPER(Raw_Data!L9)="1"), TRUE, IF(OR(UPPER(Raw_Data!L9)="FALSE", UPPER(Raw_Data!L9)="NO", UPPER(Raw_Data!L9)="0"), FALSE, "Review") ) ) ) -> TRUE
A10: =IFERROR(TRIM(Raw_Data!A10), "Review") -> EMP1008 | B10: =IFERROR(TRIM(Raw_Data!B10), "Review") -> Frank | C10: =IFERROR(TRIM(Raw_Data!C10), "Review") -> Davis | D10: =IF(Raw_Data!D10="", "", IFERROR(VALUE(Raw_Data!D10), "")) -> 35 | E10: =IFERROR(LEFT(Raw_Data!E10,SEARCH("-",Raw_Data!E10)-1),"Review") -> Admin | F10: =IFERROR(_xlfn.TEXTAFTER(Raw_Data!E10,"-"),"Review") -> Nevada | G10: =IFERROR(TRIM(Raw_Data!F10), "Review") -> Inactive | H10: =IFERROR(TEXT(Raw_Data!G10, "YYYY-MM-DD"),"Review") -> 2023-12-08 | I10: =IF(Raw_Data!H10="", "", IFERROR(VALUE(Raw_Data!H10), "")) -> 115565.82 | J10: =IF(Raw_Data!I10="", "", IF(ISNUMBER(FIND("@", Raw_Data!I10)), Raw_Data!I10, "Review")) -> frank.davis@example.com | K10: =IFERROR(TEXT(ABS(Raw_Data!J10), "0"), "Review") -> 4177656123 | L10: =IFERROR(TRIM(Raw_Data!K10), "Review") -> Excellent | M10: =IF(Raw_Data!L10="", "", IF(ISLOGICAL(Raw_Data!L10), Raw_Data!L10, IF(OR(UPPER(Raw_Data!L10)="TRUE", UPPER(Raw_Data!L10)="YES", UPPER(Raw_Data!L10)="1"), TRUE, IF(OR(UPPER(Raw_Data!L10)="FALSE", UPPER(Raw_Data!L10)="NO", UPPER(Raw_Data!L10)="0"), FALSE, "Review") ) ) ) -> TRUE
A11: =IFERROR(TRIM(Raw_Data!A11), "Review") -> EMP1009 | B11: =IFERROR(TRIM(Raw_Data!B11), "Review") -> Charlie | C11: =IFERROR(TRIM(Raw_Data!C11), "Review") -> Johnson | D11: =IF(Raw_Data!D11="", "", IFERROR(VALUE(Raw_Data!D11), "")) | E11: =IFERROR(LEFT(Raw_Data!E11,SEARCH("-",Raw_Data!E11)-1),"Review") -> DevOps | F11: =IFERROR(_xlfn.TEXTAFTER(Raw_Data!E11,"-"),"Review") -> New York | G11: =IFERROR(TRIM(Raw_Data!F11), "Review") -> Active | H11: =IFERROR(TEXT(Raw_Data!G11, "YYYY-MM-DD"),"Review") -> 2022-08-04 | I11: =IF(Raw_Data!H11="", "", IFERROR(VALUE(Raw_Data!H11), "")) -> 76561.88 | J11: =IF(Raw_Data!I11="", "", IF(ISNUMBER(FIND("@", Raw_Data!I11)), Raw_Data!I11, "Review")) -> charlie.johnson@example.com | K11: =IFERROR(TEXT(ABS(Raw_Data!J11), "0"), "Review") -> 8156985699 | L11: =IFERROR(TRIM(Raw_Data!K11), "Review") -> Excellent | M11: =IF(Raw_Data!L11="", "", IF(ISLOGICAL(Raw_Data!L11), Raw_Data!L11, IF(OR(UPPER(Raw_Data!L11)="TRUE", UPPER(Raw_Data!L11)="YES", UPPER(Raw_Data!L11)="1"), TRUE, IF(OR(UPPER(Raw_Data!L11)="FALSE", UPPER(Raw_Data!L11)="NO", UPPER(Raw_Data!L11)="0"), FALSE, "Review") ) ) ) -> TRUE
A12: =IFERROR(TRIM(Raw_Data!A12), "Review") -> EMP1010 | B12: =IFERROR(TRIM(Raw_Data!B12), "Review") -> David | C12: =IFERROR(TRIM(Raw_Data!C12), "Review") -> Williams | D12: =IF(Raw_Data!D12="", "", IFERROR(VALUE(Raw_Data!D12), "")) -> 35 | E12: =IFERROR(LEFT(Raw_Data!E12,SEARCH("-",Raw_Data!E12)-1),"Review") -> Cloud Tech | F12: =IFERROR(_xlfn.TEXTAFTER(Raw_Data!E12,"-"),"Review") -> New York | G12: =IFERROR(TRIM(Raw_Data!F12), "Review") -> Active | H12: =IFERROR(TEXT(Raw_Data!G12, "YYYY-MM-DD"),"Review") -> 2024-07-06 | I12: =IF(Raw_Data!H12="", "", IFERROR(VALUE(Raw_Data!H12), "")) -> 72081.71 | J12: =IF(Raw_Data!I12="", "", IF(ISNUMBER(FIND("@", Raw_Data!I12)), Raw_Data!I12, "Review")) -> david.williams@example.com | K12: =IFERROR(TEXT(ABS(Raw_Data!J12), "0"), "Review") -> 2720634590 | L12: =IFERROR(TRIM(Raw_Data!K12), "Review") -> Average | M12: =IF(Raw_Data!L12="", "", IF(ISLOGICAL(Raw_Data!L12), Raw_Data!L12, IF(OR(UPPER(Raw_Data!L12)="TRUE", UPPER(Raw_Data!L12)="YES", UPPER(Raw_Data!L12)="1"), TRUE, IF(OR(UPPER(Raw_Data!L12)="FALSE", UPPER(Raw_Data!L12)="NO", UPPER(Raw_Data!L12)="0"), FALSE, "Review") ) ) ) -> FALSE
A13: =IFERROR(TRIM(Raw_Data!A13), "Review") -> EMP1011 | B13: =IFERROR(TRIM(Raw_Data!B13), "Review") -> David | C13: =IFERROR(TRIM(Raw_Data!C13), "Review") -> Davis | D13: =IF(Raw_Data!D13="", "", IFERROR(VALUE(Raw_Data!D13), "")) | E13: =IFERROR(LEFT(Raw_Data!E13,SEARCH("-",Raw_Data!E13)-1),"Review") -> DevOps | F13: =IFERROR(_xlfn.TEXTAFTER(Raw_Data!E13,"-"),"Review") -> California | G13: =IFERROR(TRIM(Raw_Data!F13), "Review") -> Active | H13: =IFERROR(TEXT(Raw_Data!G13, "YYYY-MM-DD"),"Review") -> 2023-09-04 | I13: =IF(Raw_Data!H13="", "", IFERROR(VALUE(Raw_Data!H13), "")) -> 84946.19 | J13: =IF(Raw_Data!I13="", "", IF(ISNUMBER(FIND("@", Raw_Data!I13)), Raw_Data!I13, "Review")) -> david.davis@example.com | K13: =IFERROR(TEXT(ABS(Raw_Data!J13), "0"), "Review") -> 1238296576 | L13: =IFERROR(TRIM(Raw_Data!K13), "Review") -> Poor | M13: =IF(Raw_Data!L13="", "", IF(ISLOGICAL(Raw_Data!L13), Raw_Data!L13, IF(OR(UPPER(Raw_Data!L13)="TRUE", UPPER(Raw_Data!L13)="YES", UPPER(Raw_Data!L13)="1"), TRUE, IF(OR(UPPER(Raw_Data!L13)="FALSE", UPPER(Raw_Data!L13)="NO", UPPER(Raw_Data!L13)="0"), FALSE, "Review") ) ) ) -> TRUE
... A1021: =IFERROR(TRIM(Raw_Data!A1021), "Review") -> EMP2019 | B1021: =IFERROR(TRIM(Raw_Data!B1021), "Review") -> Heidi | C1021: =IFERROR(TRIM(Raw_Data!C1021), "Review") -> Jones | D1021: =IF(Raw_Data!D1021="", "", IFERROR(VALUE(Raw_Data!D1021), "")) -> 30 | E1021: =IFERROR(LEFT(Raw_Data!E1021,SEARCH("-",Raw_Data!E1021)-1),"Review") -> DevOps | F1021: =IFERROR(_xlfn.TEXTAFTER(Raw_Data!E1021,"-"),"Review") -> Illinois | G1021: =IFERROR(TRIM(Raw_Data!F1021), "Review") -> Pending | H1021: =IFERROR(TEXT(Raw_Data!G1021, "YYYY-MM-DD"),"Review") -> 2021-02-22 | I1021: =IF(Raw_Data!H1021="", "", IFERROR(VALUE(Raw_Data!H1021), "")) -> 77764.24 | J1021: =IF(Raw_Data!I1021="", "", IF(ISNUMBER(FIND("@", Raw_Data!I1021)), Raw_Data!I1021, "Review")) -> heidi.jones@example.com | K1021: =IFERROR(TEXT(ABS(Raw_Data!J1021), "0"), "Review") -> 7629745492 | L1021: =IFERROR(TRIM(Raw_Data!K1021), "Review") -> Average | M1021: =IF(Raw_Data!L1021="", "", IF(ISLOGICAL(Raw_Data!L1021), Raw_Data!L1021, IF(OR(UPPER(Raw_Data!L1021)="TRUE", UPPER(Raw_Data!L1021)="YES", UPPER(Raw_Data!L1021)="1"), TRUE, IF(OR(UPPER(Raw_Data!L1021)="FALSE", UPPER(Raw_Data!L1021)="NO", UPPER(Raw_Data!L1021)="0"), FALSE, "Review") ) ) ) -> FALSE

Sheet Summary_Dashboard
A1: HR Operations Executive Dashboard
A3: Total Payroll | C3: Average Salary | E3: Total Headcount
A4: =SUM(HR_Data[Salary]) -> 84814436 | C4: =AVERAGE(HR_Data[Salary]) -> 85155.056 | E4: =COUNTA(HR_Data[Employee_ID]) -> 1020
A7: Department Breakdown | E7: Region Breakdown
A8: Department | B8: Employees | C8: Payroll | E8: Region | F8: Employees | G8: Payroll
A9: Admin | B9: 166 | C9: 13715900 | E9: California | F9: 187 | G9: 15855823
A10: Cloud Tech | B10: 146 | C10: 11974148 | E10: Florida | F10: 185 | G10: 15622192
A11: DevOps | B11: 189 | C11: 15826948 | E11: Illinois | F11: 165 | G11: 13899966
A12: Finance | B12: 170 | C12: 13816423 | E12: Nevada | F12: 169 | G12: 13878594
A13: HR | B13: 171 | C13: 14274098 | E13: New York | F13: 161 | G13: 13234498
A14: Sales | B14: 178 | C14: 15206919 | E14: Texas | F14: 153 | G14: 12323363
A15: Grand Total | B15: 1020 | C15: 84814436 | E15: Grand Total | F15: 1020 | G15: 84814436
A17: Performance Breakdown
A18: Performance Score | B18: Employees | C18: Payroll
A19: Excellent | B19: 267 | C19: 22111636
A20: Good | B20: 270 | C20: 22448077
A21: Average | B21: 267 | C21: 22142075
A22: Poor | B22: 216 | C22: 18112648
A23: Grand Total | B23: 1020 | C23: 84814436
